Workbook

Sheet Project Overview
B2: AVENUE SUPERMARTS LIMITED (DMART)
B3: AI-ENABLED FINANCIAL STATEMENT ANALYSIS
B4: FY 2021 – FY 2022
B5: Advanced Excel | Financial Analysis | AI-Assisted Analytics | Executive Dashboard
B7: PROJECT PROFILE | K7: AI-ENABLED WORKFLOW
B8: Prepared By | C8: Ayush Nitin Jagtap | K8: AI Tools: ChatGPT + Microsoft Copilot
B9: Professional Profile | C9: Accounting | Finance & Business Analysis | Financial Modeling | AI - Integrated Finance | K9: • Financial-data structuring and organization
B10: Education | C10: B.Com – Business Administration | M.Com – Advanced Accounting & Income Tax | K10: • Formula development and analytical review support
B11: Project Type | C11: Independent Portfolio Project – Financial Analysis | K11: • Financial trend and ratio interpretation
B12: Company | C12: Avenue Supermarts Limited (DMart) | K12: • Insight generation and commentary support
B13: Period | C13: FY2021 – FY2022 | K13: • Dashboard structure and presentation support
B14: Reporting Basis | C14: Consolidated Financial Statements | K14: HUMAN-VERIFIED WORKFLOW AI was used as a supporting analytical tool. Financial figures, calculations, interpretations and final outputs were reviewed against the underlying financial statements and Excel analysis.
B15: Currency | C15: ₹ Crore
B18: PROJECT OBJECTIVE
B19: To evaluate DMart’s financial performance and position through comparative financial statement analysis, profitability, liquidity, working capital, cash-flow, efficiency and solvency analysis for FY2021–FY2022, and present the findings through an executive financial dashboard.
B23: ADVANCED EXCEL & ANALYTICS | K23: FINANCIAL ANALYTICAL FRAMEWORK
B24: • Power Query – financial statement / PDF data extraction | K24: • Revenue & Profitability Analysis
B25: • Formula-driven financial analysis | K25: • Balance Sheet & Financial Position
B26: • Structured analytical tables and calculations | K26: • Cash Flow Analysis
B27: • Comparative year-on-year analysis | K27: • Working Capital Analysis
B28: • Financial ratio calculations | K28: • Liquidity & Profitability Ratios
B29: • KPI cards and executive dashboard design | K29: • Efficiency & Asset Utilization Ratios
B30: • Charts and financial data visualization | K30: • Solvency & Interest Coverage
B31: • Professional Excel formatting and presentation | K31: • Business Interpretation & Executive Insights
B33: PROJECT METHODOLOGY
B34: 1 | C34: Annual Report | G34: Source financial statements from DMart FY2021–22 Annual Report
B35: 2 | C35: Data Extraction | G35: Extract and structure consolidated financial statement data in Excel
B36: 3 | C36: Financial Analysis | G36: Perform YoY, profitability, balance sheet, cash-flow and working-capital analysis
B37: 4 | C37: Ratio Analysis | G37: Calculate liquidity, profitability, efficiency and solvency ratios
B38: 5 | C38: AI-Assisted Review | G38: Use ChatGPT + Copilot as supporting tools for analytical review and insight development
B39: 6 | C39: Executive Dashboard | G39: Convert validated analysis into KPI cards, charts and management-style insights
B42: PROJECT DELIVERABLES | K42: DATA SOURCE & PORTFOLIO NOTE
B43: ✓ Consolidated financial statement analysis | K43: DATA SOURCE Avenue Supermarts Limited (DMart) Annual Report FY2021–22 PORTFOLIO NOTE Independently prepared for academic and portfolio purposes using publicly available financial information.
B44: ✓ Revenue & profitability analysis
B45: ✓ Balance sheet analysis
B46: ✓ Cash-flow analysis
B47: AI / VERIFICATION NOTE: AI tools were used as supporting tools for analysis and presentation. Final financial figures, formulas, analytical conclusions and dashboard outputs were reviewed against the underlying Excel calculations and source financial statements.
B49: DMART | FINANCIAL ANALYSIS PROJECT | AI-Enabled Financial Analysis | ChatGPT + Microsoft Copilot
B50: ✓ Executive financial dashboard

Sheet Balance Sheet
A1: Consolidated Balance Sheet as at 31st March, 2022 All figures are in Cr
C2: 31st March, 2022 | D2: 31st March, 2021
B3: Assets
B4: Non-current assets
A5: (a) | B5: Property, plant and equipment | C5: 7,770.46 | D5: 5,938.50
A6: (b) | B6: Capital work-in-progress | C6: 1,129.34 | D6: 1,019.59
A7: (c) | B7: Right -of- use assets | C7: 1,388.65 | D7: 960.24
A8: (d) | B8: Investment properties | C8: 9.03 | D8: 9.57
A9: (e) | B9: Goodwill | C9: 78.27 | D9: 78.27
A10: (f) | B10: Intangible assets | C10: 13.61 | D10: 22.22
A11: (g) | B11: Financial assets
B12: (i) Investments | C12: 0.01 | D12: -
B13: (ii) Other non-current financial assets | C13: 1,262.70 | D13: 1,109.28
A14: (h) | B14: Income tax assets (net) | C14: 2.28 | D14: 1.63
A15: (i) | B15: Deferred tax assets (net) | C15: 1.66 | D15: 0.92
A16: (j) | B16: Other non-current assets | C16: 373.78 | D16: 454.62
B17: Total non-current assets | C17: 12,029.79 | D17: 9,594.84
B18: Current assets
A19: (a) | B19: Inventories | C19: 2,742.66 | D19: 2,248.28
A20: (b) | B20: Financial assets
B21: (i) Investments | C21: 5.93 | D21: 2.95
B22: (ii)Trade receivables | C22: 66.89 | D22: 43.58
B23: (iv) Cash and cash equivalents | C23: 95.12 | D23: 191.50
B24: (v) Bank balances other than cash and cash equivalents | C24: 203.46 | D24: 1,254.08
B25: (vi) Other current financial assets | C25: 127.46 | D25: 167.91
A26: (c) | B26: Other current assets | C26: 201.33 | D26: 152.83
B27: Total current assets | C27: 3,442.85 | D27: 4,061.13
B28: Total assets | C28: 15,472.64 | D28: 13,655.97
B29: Equity and liabilities
B30: Equity
A31: (a) | B31: Equity share capital | C31: 647.77 | D31: 647.77
A32: (b) | B32: Other equity | C32: 13,029.87 | D32: 11,535.94
B33: Equity attributable to equity holders of the parent | C33: 13,677.64 | D33: 12,183.71
B34: Non-controlling interest | C34: 0.25 | D34: 0.40
B35: Total equity | C35: 13,677.89 | D35: 12,184.11
B36: Liabilities
B37: Non-current liabilities
A38: (a) | B38: Financial liabilities
B39: (ia) Lease liability | C39: 507.15 | D39: 312.01
B40: (ii) Other non-current financial liabilities | C40: 0.41 | D40: 0.44
...

Sheet Profit and loss account 
A1: Statement of Consolidated Profit and Loss for the year ended 31st March, 2022
B2: 31st March, 2022 | C2: 31st March, 2021
A3: Income
A4: Revenue from operations | B4: 30,976.27 | C4: 24,143.06
A5: Other income | B5: 117.49 | C5: 196.21
A6: Total income | B6: 31,093.76 | C6: 24,339.27
A7: Expenses
A8: Purchase of stock-in-trade | B8: 26,891.77 | C8: 20,855.56
A9: Changes in inventories of stock-in-trade | B9: (494.38) | C9: (300.88)
A10: Employee benefits expenses | B10: 616.21 | C10: 536.57
A11: Finance costs | B11: 53.79 | C11: 41.65
A12: Depreciation and amortisation expense | B12: 498.08 | C12: 414.16
A13: Other expenses | B13: 1,464.17 | C13: 1,308.76
A14: Total Expenses | B14: 29,029.64 | C14: 22,855.82
A15: Profit before tax | B15: 2,064.12 | C15: 1,483.45
A16: Tax Expense
A17: Current tax | B17: 546.33 | C17: 394.69
A18: Deferred tax charge | B18: 12.10 | C18: 3.17
A19: Adjustment of tax related to earlier years | B19: 13.29 | C19: (13.84)
A20: Total Tax expenses | B20: 571.72 | C20: 384.02
A21: Net profit after tax | B21: 1,492.40 | C21: 1,099.43
A22: Other Comprehensive Income
A23: Items that will not be reclassified to profit or loss
A24: Re-measurements loss on defined benefit plans | B24: (6.14) | C24: (2.35)
A25: Less: Income tax effect | B25: 1.11 | C25: 0.45
A26: Net other comprehensive income not to be reclassified to profit or loss in subsequent year | B26: (5.03) | C26: (1.90)
A27: Total comprehensive income for the year | B27: 1,487.37 | C27: 1,097.53
A28: Profit for the year | B28: 1,492.40 | C28: 1,099.43
A29: Attributable to:
A30: Equity holders of the parent | B30: 1,492.55 | C30: 1,099.49
A31: Non-controlling interests | B31: (0.15) | C31: (0.06)
A32: Total comprehensive income for the year | B32: 1,487.37 | C32: 1,097.53
A33: Attributable to:
A34: Equity holders of the parent | B34: 1,487.52 | C34: 1,097.59
A35: Non-controlling interests | B35: (0.15) | C35: (0.06)
A36: Earnings per equity share of Rs 10 each: (in Rs)
A37: Basic | B37: 23.04 | C37: 16.97
A38: Diluted | B38: 22.86 | C38: 16.85
A39: Summary of significant accounting policies

Sheet Cash flow statement 
A1: Statement of Consolidated Cash Flows for the year ended 31st March, 2022
B2: For the year ended | C2: For the year ended
B3: 31st March, 2022 | C3: 31st March, 2021
A4: Cash flow from operating activities:
A5: Profit before tax | B5: 2,064.12 | C5: 1,483.45
A6: Adjustments for:
A7: Depreciation and amortisation expenses | B7: 498.08 | C7: 414.16
A8: Finance cost | B8: 53.79 | C8: 41.65
A9: Interest income | B9: (103.96) | C9: (178.13)
A10: Profit on sale of investments | B10: (3.66) | C10: (2.56)
A11: Expense on employee stock option scheme | B11: 6.42 | C11: 6.38
A12: Rent income | B12: (3.55) | C12: (2.89)
A13: Loss on disposal of property, plant and equipment (net) | B13: 3.85 | C13: 1.78
B14: 450.97 | C14: 280.39
A15: Operating profit before working capital changes | B15: 2,515.09 | C15: 1,763.84
A16: Adjustments for:
A17: Increase in trade payables | B17: 11.07 | C17: 144.68
A18: Increase in current provisions | B18: 6.53 | C18: 6.24
A19: Increase/ (decrease) in other current financial liabilities | B19: (6.91) | C19: 48.87
A20: Increase in other current liabilities | B20: 17.64 | C20: 20.03
A21: Increase in non-current provisions | B21: 2.42 | C21: 0.97
A22: Decrease in other non-current financial liabilities | B22: (0.03) | C22: (0.03)
A23: Increase in trade receivables | B23: (23.31) | C23: (24.03)
A24: Increase in inventories | B24: (494.38) | C24: (300.88)
A25: (Increase)/ decrease in current investments | B25: (2.98) | C25: 11.73
A26: Increase in other non-current financial assets | B26: (6.79) | C26: (15.26)
A27: (Increase)/ decrease in bank balances other than cash and cash equivalents | B27: 0.62 | C27: (2.07)
A28: Increase in other current assets | B28: (48.96) | C28: (4.79)
A29: Increase in other current financial assets | B29: (37.41) | C29: (12.59)
B30: (582.49) | C30: (127.13)
A31: Cash flow from operating activities | B31: 1,932.60 | C31: 1,636.71
A32: Direct taxes paid (net of refunds) | B32: (560.25) | C32: (261.57)
A33: Net cash flow from operating activities | B33: 1,372.35 | C33: 1,375.14
A34: Cash flow from investing activities:
A35: Proceeds from disposal of property, plant and equipment | B35: 20.92 | C35: 1.88
A36: Realisation from Fixed Deposits of Qualified institutional placement proceeds | B36: 1,050.00 | C36: 783.00
A37: Interest received | B37: 42.80 | C37: 129.09
A38: Gain on sale of investments | B38: 3.66 | C38: 2.56
A39: Rent income received | B39: 3.55 | C39: 2.89
A40: Purchase of property, plant and equipment/ intangible assets/investment properties | B40: (2,410.42) | C40: (2,029.42)
...

Sheet Revenue & Profitability
C1: Revenue & Profitability Analysis | I1: “Value for Customers. Growth for a Better Tomorrow.”
B2: Revenue Analysis | G2: Profitability Analysis
B3: Metric | C3: FY2021 | D3: FY2022 | E3: Change % | F3: Trend | G3: Metric | H3: FY2021 | I3: FY2022 | J3: Change % | K3: Trend
B4: Revenue from Operations | C4: 24143.06 | D4: 30976.27 | E4: =(D4-C4)/C4 -> 0.28302999 | F4: =IF(E4>0,"↑",IF(E4<0,"↓","→")) -> ↑ | G4: Revenue from Operations | H4: =C4 -> 24143.06 | I4: =D4 -> 30976.27 | J4: =(I4-H4)/H4 -> 0.28302999 | K4: =IF(J4>0,"↑",IF(J4<0,"↓","→")) -> ↑
B5: Other Income | C5: 196.21 | D5: 117.49 | E5: =(D5-C5)/C5 -> -0.40120279 | F5: =IF(E5>0,"↑",IF(E5<0,"↓","→")) -> ↓ | G5: Profit Before Tax | H5: =C8 -> 1483.45 | I5: =D8 -> 2064.12 | J5: =(I5-H5)/H5 -> 0.39143213 | K5: =IF(J5>0,"↑",IF(J5<0,"↓","→")) -> ↑
B6: Total Income | C6: 24339.27 | D6: 31093.76 | E6: =(D6-C6)/C6 -> 0.27751407 | F6: =IF(E6>0,"↑",IF(E6<0,"↓","→")) -> ↑ | G6: Profit After Tax | H6: =C10 -> 1099.43 | I6: =D10 -> 1492.4 | J6: =(I6-H6)/H6 -> 0.35743067 | K6: =IF(J6>0,"↑",IF(J6<0,"↓","→")) -> ↑
B7: Total Expenses | C7: 22855.82 | D7: 29029.64 | E7: =(D7-C7)/C7 -> 0.27012026 | F7: =IF(E7>0,"↑",IF(E7<0,"↓","→")) -> ↑ | G7: PBT Margin | H7: =H5/H4 -> 0.061444158 | I7: =I5/I4 -> 0.066635525 | J7: =(I7-H7)/H7 -> 0.084489175 | K7: =IF(J7>0,"↑",IF(J7<0,"↓","→")) -> ↑
B8: Profit Before Tax | C8: 1483.45 | D8: 2064.12 | E8: =(D8-C8)/C8 -> 0.39143213 | F8: =IF(E8>0,"↑",IF(E8<0,"↓","→")) -> ↑ | G8: PAT Margin | H8: =H6/H4 -> 0.045538138 | I8: =I6/I4 -> 0.048178816 | J8: =(I8-H8)/H8 -> 0.057988263 | K8: =IF(J8>0,"↑",IF(J8<0,"↓","→")) -> ↑
B9: Tax Expense | C9: 384.02 | D9: 571.72 | E9: =(D9-C9)/C9 -> 0.48877663 | F9: =IF(E9>0,"↑",IF(E9<0,"↓","→")) -> ↑
B10: Profit After Tax | C10: 1099.43 | D10: 1492.4 | E10: =(D10-C10)/C10 -> 0.35743067 | F10: =IF(E10>0,"↑",IF(E10<0,"↓","→")) -> ↑
B12: Expense Analysis | G12: Expense Insight
B13: Expense | C13: FY2021 | D13: FY2022 | E13: Change % | F13: Trend
B14: Purchase of Stock-in-Trade | C14: ='Profit and loss account '!C8 -> 20,855.56 | D14: ='Profit and loss account '!B8 -> 26,891.77 | E14: =(D14-C14)/C14 -> 0.28942929 | F14: =IF(E14>0,"↑",IF(E14<0,"↓","→")) -> ↑ | G14: Purchases increased broadly in line with revenue.
B15: Employee Benefits Expense | C15: ='Profit and loss account '!C10 -> 536.57 | D15: ='Profit and loss account '!B10 -> 616.21 | E15: =(D15-C15)/C15 -> 0.14842425 | F15: =IF(E15>0,"↑",IF(E15<0,"↓","→")) -> ↑ | G15: Employee costs grew slower than revenue.
B16: Finance Costs | C16: ='Profit and loss account '!C11 -> 41.65 | D16: ='Profit and loss account '!B11 -> 53.79 | E16: =(D16-C16)/C16 -> 0.29147659 | F16: =IF(E16>0,"↑",IF(E16<0,"↓","→")) -> ↑ | G16: Finance costs grew slightly faster than revenue.
B17: Depreciation & Amortisation | C17: ='Profit and loss account '!C12 -> 414.16 | D17: ='Profit and loss account '!B12 -> 498.08 | E17: =(D17-C17)/C17 -> 0.202627 | F17: =IF(E17>0,"↑",IF(E17<0,"↓","→")) -> ↑ | G17: Depreciation increased but remained below revenue growth.
B18: Other Expenses | C18: ='Profit and loss account '!C13 -> 1,308.76 | D18: ='Profit and loss account '!B13 -> 1,464.17 | E18: =(D18-C18)/C18 -> 0.11874599 | F18: =IF(E18>0,"↑",IF(E18<0,"↓","→")) -> ↑ | G18: Other expenses grew slower than revenue.
B19: Total Expenses | C19: 22855.82 | D19: 29029.64 | E19: =(D19-C19)/C19 -> 0.27012026 | F19: =IF(E19>0,"↑",IF(E19<0,"↓","→")) -> ↑ | G19: Total expenses grew slightly slower than revenue.
A20: KEY ANALYST TAKEAWAY
A21: DMart delivered strong FY2022 growth, with revenue increasing 28.30% and PBT and PAT growing faster than revenue. PBT and PAT margins improved modestly, while most major operating expenses remained broadly aligned with or below revenue growth. | I21: 🤖 AI-Enabled Financial Analysis | ChatGPT + Microsoft Copilot
A23: Learn • Analyse • Grow | Revenue & Profitability Analysis | A Project by Ayush Nitin Jagtap

Sheet Balance Sheet Analysis
A1: DMart | C1: Balance Sheet Analysis | G1: “Value for Customers. Growth for a Better Tomorrow.”
B2: Balance Sheet Analysis | G2: Balance Sheet Insights
B3: Metric | C3: FY2021 | D3: FY2022 | E3: Change % | F3: Trend | G3: Metric | H3: FY2021 | I3: FY2022 | J3: Change % | K3: Trend
B4: Total Assets | C4: ='Balance Sheet'!D28 -> 13,655.97 | D4: ='Balance Sheet'!C28 -> 15,472.64 | E4: =(D4-C4)/C4 -> 0.13303119 | F4: =IF(E4>0,"↑",IF(E4<0,"↓","→")) -> ↑ | G4: Current Assets | H4: ='Balance Sheet'!D27 -> 4,061.13 | I4: ='Balance Sheet'!C27 -> 3,442.85 | J4: =(I4-H4)/H4 -> -0.15224334 | K4: =IF(J4>0,"↑",IF(J4<0,"↓","→")) -> ↓
B5: Total Equity | C5: ='Balance Sheet'!D35 -> 12,184.11 | D5: ='Balance Sheet'!C35 -> 13,677.89 | E5: =(D5-C5)/C5 -> 0.12260067 | F5: =IF(E5>0,"↑",IF(E5<0,"↓","→")) -> ↑ | G5: Current Liabilities | H5: ='Balance Sheet'!D54 -> 1,105.77 | I5: ='Balance Sheet'!C54 -> 1,218.29 | J5: =(I5-H5)/H5 -> 0.10175715 | K5: =IF(J5>0,"↑",IF(J5<0,"↓","→")) -> ↑
B6: Total Liabilities | C6: 1471.86 | D6: 1794.75 | E6: =(D6-C6)/C6 -> 0.21937548 | F6: =IF(E6>0,"↑",IF(E6<0,"↓","→")) -> ↑
B7: Current Assets | C7: ='Balance Sheet'!D27 -> 4,061.13 | D7: ='Balance Sheet'!C27 -> 3,442.85 | E7: =(D7-C7)/C7 -> -0.15224334 | F7: =IF(E7>0,"↑",IF(E7<0,"↓","→")) -> ↓
B8: Current Liabilities | C8: 1105.77 | D8: ='Balance Sheet'!C54 -> 1,218.29 | E8: =(D8-C8)/C8 -> 0.10175715 | F8: =IF(E8>0,"↑",IF(E8<0,"↓","→")) -> ↑
B9: Cash & Cash Equivalents | C9: ='Balance Sheet'!D23 -> 191.50 | D9: ='Balance Sheet'!C23 -> 95.12 | E9: =(D9-C9)/C9 -> -0.50328982 | F9: =IF(E9>0,"↑",IF(E9<0,"↓","→")) -> ↓ | G9: What the movement indicates
B10: Inventories | C10: ='Balance Sheet'!D19 -> 2,248.28 | D10: ='Balance Sheet'!C19 -> 2,742.66 | E10: =(D10-C10)/C10 -> 0.21989254 | F10: =IF(E10>0,"↑",IF(E10<0,"↓","→")) -> ↑ | G10: Current assets declined while current liabilities increased, reducing the short-term financial cushion.
B11: Trade Receivables | C11: 43.58 | D11: 66.89 | E11: =(D11-C11)/C11 -> 0.53487838 | F11: =IF(E11>0,"↑",IF(E11<0,"↓","→")) -> ↑ | G11: Cash declined materially, while inventory and receivables increased; working-capital composition changed significantly.
B12: Consolidated Financial Statements | FY2021 vs FY2022 | Source: Annual Report 2021–22 | Financial figures in ₹ Cr
B13: Key Balance Sheet Findings | G13: Analyst Interpretation
B15: Assets & Equity | C15: Evidence: Total Assets +13.30%; Equity +12.26%, indicating balance-sheet expansion. | G15: The balance sheet expanded during FY2022, supported primarily by growth in equity and assets.
B16: Liability Structure | C16: Evidence: Total liabilities increased 21.94%, growing faster than total assets and requiring closer review. | G16: Total liabilities increased 21.94%, growing faster than total assets and requiring closer review.
B17: Liquidity | C17: Evidence: Current assets fell 15.22% while current liabilities rose 10.18%, reducing the short-term cushion. | G17: Current assets fell 15.22% while current liabilities rose 10.18%, reducing the short-term cushion.
B18: Cash Position | C18: Evidence: Cash and cash equivalents declined 50.33%, materially lowering immediate liquidity. | G18: Cash and cash equivalents declined 50.33%, materially lowering immediate liquidity.
B19: Inventory | C19: Evidence: Inventories increased 21.99%, making inventory efficiency an important working-capital consideration. | G19: Inventories increased 21.99%, making inventory efficiency an important working-capital consideration.
B20: Receivables | C20: Evidence: Trade receivables increased 53.49%, highlighting a need to examine collection and working-capital dynamics. | G20: Trade receivables increased 53.49%, highlighting a need to examine collection and working-capital dynamics.
B21: KEY ANALYST TAKEAWAY
B22: DMart's balance sheet expanded in FY2022, with total assets and equity increasing. However, current assets and cash declined while current liabilities increased. The rise in inventory and trade receivables highlights working-capital areas requiring further analysis. | I22: 🤖 AI-Enabled Financial Analysis | ChatGPT + Microsoft Copilot
A24: Learn • Analyse • Grow | Balance Sheet Analysis | A Project by Ayush Nitin Jagtap

Sheet Cash Flow Analysis
C1: Cash Flow Analysis | G1: “Value for Customers. Growth for a Better Tomorrow.”
B3: Cash Flow Summary Analysis | G3: Analyst Interpretation
B4: Cash Flow Metric | C4: FY2021 | D4: FY2022 | E4: Change % | F4: Trend
B5: Net Cash Flow from Operating Activities | C5: ='Cash flow statement '!C33 -> 1,375.14 | D5: ='Cash flow statement '!B33 -> 1,372.35 | E5: =(D5-C5)/C5*100 -> -0.20288843 | F5: =IF(E5>0,"↑",IF(E5<0,"↓","→")) -> ↓ | G5: The -0.20% movement is tiny, so "broadly stable" is appropriate.
B6: Net Cash Flow Used in Investing Activities | C6: ='Cash flow statement '!C41 -> (1,110.00) | D6: ='Cash flow statement '!B41 -> (1,289.49) | E6: =(D6-C6)/ABS(C6) -> -0.1617027 | F6: =IF(E6>0,"↑",IF(E6<0,"↓","→")) -> ↓ | G6: Investing cash outflow increased, indicating greater cash deployment toward investing activities
B7: Net Cash Flow Used in Financing Activities | C7: ='Cash flow statement '!C49 -> (179.50) | D7: ='Cash flow statement '!B49 -> (179.24) | E7: =(D7-C7)/ABS(C7) -> 0.001448468 | F7: → | G7: Financing cash outflow remained broadly stable, with a marginal reduction in the outflow.
B8: Net Increase/(Decrease) in Cash & Cash Equivalents | C8: ='Cash flow statement '!C50 -> 85.64 | D8: ='Cash flow statement '!B50 -> (96.38) | E8: =(D8-C8)/C8*100 -> -212.54087 | F8: =IF(E8>0,"↑",IF(E8<0,"↓","→")) -> ↓ | G8: Net cash moved from an increase of ₹85.64 Cr to a decrease of ₹96.38 Cr, representing a ₹182.02 Cr negative swing
B9: Consolidated Cash Flow Statement | FY2021 vs FY2022 | Source: Annual Report 2021–22 | Financial figures in ₹ Cr
B10: Key Cash Flow Findings | G10: Financial Analysis View
B11: Operating Cash Flow | C11: CFO remained broadly stable at ₹1,375.14 Cr in FY2021 and ₹1,372.35 Cr in FY2022. | G11: CFO remained broadly stable at ₹1,375.14 Cr in FY2021 and ₹1,372.35 Cr in FY2022.
B12: Investing Cash Flow | C12: Investing outflow increased from ₹1,110.00 Cr to ₹1,289.49 Cr. | G12: Investing outflow increased from ₹1,110.00 Cr to ₹1,289.49 Cr.
B13: Financing Cash Flow | C13: Financing outflow remained broadly stable at ₹179.50 Cr and ₹179.24 Cr. | G13: Financing outflow remained broadly stable at ₹179.50 Cr and ₹179.24 Cr.
B14: Net Cash Movement | C14: Net cash changed from an increase of ₹85.64 Cr to a decrease of ₹96.38 Cr. | G14: Net cash changed from an increase of ₹85.64 Cr to a decrease of ₹96.38 Cr.
B15: KEY ANALYST TAKEAWAY
B16: DMart maintained strong operating cash generation in FY2022 but deployed substantial cash toward investing activities. Consequently, the company experienced a net decrease in cash during the year. Overall, the cash-flow position was mixed, with healthy operating cash generation but significant cash deployment. | H16: 🤖 AI-Enabled Financial Analysis | ChatGPT + Microsoft Copilot
B18: Methodology: Original source formulas and source-cell references are preserved exactly. Change % display is formatted for readability without changing the original formulas.

Sheet Working Capital Analysis
C1: Working Capital Analysis | G1: “Value for Customers. Growth for a Better Tomorrow.”
B2: Working Capital Metrics | G2: Analyst Interpretation
B3: Working Capital Metric | C3: FY2021 | D3: FY2022 | E3: Change % | F3: Trend | G3: • Inventory: +21.99% — higher funds tied up in stock. • Trade Receivables: +53.49% — collection and working-capital efficiency merit attention. • Trade Payables: +1.91% — broadly stable. • Current Assets: −15.22% — lower short-term asset cushion. • Current Liabilities: +10.18% — higher short-term obligations.
B4: Inventory | C4: ='Balance Sheet'!D19 -> 2,248.28 | D4: ='Balance Sheet'!C19 -> 2,742.66 | E4: =(Table12[[#This Row],[FY2022]]-Table12[[#This Row],[FY2021]])/Table12[[#This Row],[FY2021]] -> 0.21989254 | F4: =IF(E4>0,"↑",IF(E4<0,"↓","→")) -> ↑
B5: Trade Receivables | C5: ='Balance Sheet'!D22 -> 43.58 | D5: ='Balance Sheet'!C22 -> 66.89 | E5: =(Table12[[#This Row],[FY2022]]-Table12[[#This Row],[FY2021]])/Table12[[#This Row],[FY2021]] -> 0.53487838 | F5: =IF(E5>0,"↑",IF(E5<0,"↓","→")) -> ↑ | G5: Net Working Capital Interpretation
B6: Trade Payables | C6: ='Balance Sheet'!D48+'Balance Sheet'!D49 -> 578.13 | D6: ='Balance Sheet'!C48+'Balance Sheet'!C49 -> 589.2 | E6: =(Table12[[#This Row],[FY2022]]-Table12[[#This Row],[FY2021]])/Table12[[#This Row],[FY2021]] -> 0.019147943 | F6: =IF(E6>0,"↑",IF(E6<0,"↓","→")) -> ↑ | G6: Net working capital declined by 24.73%, indicating a weaker short-term financial cushion.
B7: Current Assets | C7: ='Balance Sheet'!D27 -> 4,061.13 | D7: ='Balance Sheet'!C27 -> 3,442.85 | E7: =(Table12[[#This Row],[FY2022]]-Table12[[#This Row],[FY2021]])/Table12[[#This Row],[FY2021]] -> -0.15224334 | F7: =IF(E7>0,"↑",IF(E7<0,"↓","→")) -> ↓ | G7: KEY ANALYST TAKEAWAY
B8: Current Liabilities | C8: ='Balance Sheet'!D54 -> 1,105.77 | D8: ='Balance Sheet'!C54 -> 1,218.29 | E8: =(Table12[[#This Row],[FY2022]]-Table12[[#This Row],[FY2021]])/Table12[[#This Row],[FY2021]] -> 0.10175715 | F8: =IF(E8>0,"↑",IF(E8<0,"↓","→")) -> ↑ | G8: DMart's working capital position weakened in FY2022, with net working capital declining by 24.73%. Inventory and trade receivables increased, while current assets and cash declined and current liabilities increased. This points to a tighter short-term financial cushion and highlights working-capital management as an area for further analysis.
B9: Net Working Capital Analysis
B10: Net Working capital | C10: 2955.36 | D10: 2224.56 | E10: -0.24727952 | F10: =IF(E10>0,"↑",IF(E10<0,"↓","→")) -> ↓
B11: Consolidated Balance Sheet Data | FY2021 vs FY2022 | Source: Annual Report 2021–22 | Financial figures in ₹ Cr | I11: 🤖 AI-Enabled Financial Analysis | ChatGPT + Microsoft Copilot

Sheet Ratio Analysis
C1: Ratio Analysis | G1: “Value for Customers. Growth for a Better Tomorrow.”
C3: Consolidated Financial Statements | FY2021 vs FY2022
A4: ▣ COMPANY Avenue Supermarts Limited (DMart) | C4: ▣ PERIOD FY2021 – FY2022 | E4: ▥ SOURCE Annual Report 2021-22 | G4: ▤ FIGURES & FORMAT Financial figures in ₹ Cr | Ratios in × | Margins & Changes in %
B6: Ratio | C6: Formula | D6: FY2021 | E6: FY2022 | F6: Change % | G6: Trend | H6: Interpretation
A7: 01 | C7: Liquidity Ratios | E7: Measures short-term financial strength and ability to meet obligations
B8: Current Ratio | C8: Current Assets ÷ Current Liabilities | D8: ='Balance Sheet'!D27/'Balance Sheet'!D54 -> 3.6726715 | E8: ='Balance Sheet'!C27/'Balance Sheet'!C54 -> 2.8259692 | F8: =(E8-D8)/ABS(D8) -> -0.23054127 | G8: =IF(F8>0,"↑",IF(F8<0,"↓","→")) -> ↓ | H8: Decline indicates a lower short-term liquidity cushion, though the ratio remains above 2×.
B9: Quick Ratio | C9: (Current Assets − Inventory) ÷ Current Liabilities | D9: =('Balance Sheet'!D27-'Balance Sheet'!D19)/'Balance Sheet'!D54 -> 1.6394458 | E9: =('Balance Sheet'!C27-'Balance Sheet'!C19)/'Balance Sheet'!C54 -> 0.5747318 | F9: =(E9-D9)/ABS(D9) -> -0.64943532 | G9: =IF(F9>0,"↑",IF(F9<0,"↓","→")) -> ↓ | H9: Significant decline indicates greater reliance on inventory to meet short-term liabilities.
B10: Cash Ratio | C10: Cash & Cash Equivalents ÷ Current Liabilities | D10: ='Balance Sheet'!D23/'Balance Sheet'!D54 -> 0.17318249 | E10: ='Balance Sheet'!C23/'Balance Sheet'!C54 -> 0.078076648 | F10: =(E10-D10)/ABS(D10) -> -0.54916545 | G10: =IF(F10>0,"↑",IF(F10<0,"↓","→")) -> ↓ | H10: Lower cash coverage of current liabilities indicates a tighter immediate liquidity position.
A11: 02 | C11: Profitability Ratios | E11: Measures how effectively the company generates profit
B12: Gross Profit Margin | C12: Gross Profit ÷ Revenue from Operations × 100 | D12: =(24143.06-(20855.56+(-300.88)))/24143.06 -> 0.14862988 | E12: =(30976.27-(26891.77+(-494.38)))/30976.27 -> 0.14781896 | F12: =(E12-D12)/ABS(D12) -> -0.0054559417 | G12: =IF(F12>0,"↑",IF(F12<0,"↓","→")) -> ↓ | H12: Gross margin remained broadly stable, with a slight decline.
B13: PBT Margin | C13: PBT ÷ Revenue from Operations × 100 | D13: ='Revenue & Profitability'!H7 -> 0.061444158 | E13: ='Revenue & Profitability'!I7 -> 0.066635525 | F13: =(E13-D13)/ABS(D13) -> 0.084489175 | G13: =IF(F13>0,"↑",IF(F13<0,"↓","→")) -> ↑ | H13: Improved margin indicates stronger profit before tax relative to revenue.
B14: PAT Margin | C14: PAT ÷ Revenue from Operations × 100 | D14: ='Revenue & Profitability'!H8 -> 0.045538138 | E14: ='Revenue & Profitability'!I8 -> 0.048178816 | F14: =(E14-D14)/ABS(D14) -> 0.057988263 | G14: =IF(F14>0,"↑",IF(F14<0,"↓","→")) -> ↑ | H14: Improved margin indicates stronger bottom-line profitability.
B15: ROA | C15: PAT ÷ Total Assets × 100 | D15: ='Profit and loss account '!C21/'Balance Sheet'!D28*100 -> 8.0509111 | E15: ='Profit and loss account '!B21/'Balance Sheet'!C28*100 -> 9.6454128 | F15: =(E15-D15)/ABS(D15) -> 0.19805234 | G15: =IF(F15>0,"↑",IF(F15<0,"↓","→")) -> ↑ | H15: Higher ROA indicates greater profit generated relative to total assets.
B16: ROE | C16: PAT ÷ Total Equity × 100 | D16: ='Profit and loss account '!C21/'Balance Sheet'!D35*100 -> 9.023474 | E16: ='Profit and loss account '!B21/'Balance Sheet'!C35*100 -> 10.91104 | F16: =(E16-D16)/ABS(D16) -> 0.20918392 | G16: =IF(F16>0,"↑",IF(F16<0,"↓","→")) -> ↑ | H16: Higher ROE indicates improved returns generated on shareholders' equity.
B17: ROCE | C17: EBIT ÷ Capital Employed × 100 | D17: =('Profit and loss account '!C15+'Cash flow statement '!C8)/('Balance Sheet'!D28-'Balance Sheet'!D54)*100 -> 12.151998 | E17: =('Profit and loss account '!B15+'Cash flow statement '!B8)/('Balance Sheet'!C28-'Balance Sheet'!C54)*100 -> 14.857991 | F17: =(E17-D17)/ABS(D17) -> 0.22267887 | G17: =IF(F17>0,"↑",IF(F17<0,"↓","→")) -> ↑ | H17: Higher ROCE indicates more efficient use of capital employed.
A18: 03 | C18: Efficiency Ratios | E18: Measures how effectively the company uses its assets and working capital
B19: Inventory Turnover | C19: COGS ÷ Average Inventory | D19: =(20855.56-300.88)/((1947.4+2248.28)/2) -> 9.7980208 | E19: =(26891.77-494.38)/((2248.28+2742.66)/2) -> 10.578124 | F19: =(E19-D19)/ABS(D19) -> 0.0796184 | G19: =IF(F19>0,"↑",IF(F19<0,"↓","→")) -> ↑ | H19: Higher turnover indicates faster movement of inventory during the year.
B20: Receivables Turnover | C20: Revenue from Operations ÷ Average Trade Receivables | D20: =24143.06/((19.55+43.58)/2) -> 764.86805 | E20: =30976.27/((43.58+66.89)/2) -> 560.80873 | F20: =(E20-D20)/ABS(D20) -> -0.26679023 | G20: =IF(F20>0,"↑",IF(F20<0,"↓","→")) -> ↓ | H20: Lower turnover indicates receivables increased faster relative to revenue, requiring monitoring.
B21: Payables Turnover | C21: Purchases ÷ Average Trade Payables | D21: =20855.56/((433.45+578.13)/2) -> 41.233635 | E21: =26891.77/((578.13+589.2)/2) -> 46.073981 | F21: =(E21-D21)/ABS(D21) -> 0.1173883 | G21: =IF(F21>0,"↑",IF(F21<0,"↓","→")) -> ↑ | H21: Higher turnover indicates purchases were higher relative to average trade payables.
B22: Asset Turnover | C22: Revenue from Operations ÷ Average Total Assets | D22: =24143.06/((12076.16+13655.97)/2) -> 1.8764914 | E22: =30976.27/((13655.97+15472.64)/2) -> 2.1268622 | F22: =(E22-D22)/ABS(D22) -> 0.13342499 | G22: =IF(F22>0,"↑",IF(F22<0,"↓","→")) -> ↑ | H22: Higher turnover indicates improved revenue generation relative to the asset base.
A23: 04 | C23: Solvency Ratios | E23: Measures long-term financial stability and risk
B24: Debt-to-Equity | C24: Total Debt ÷ Total Equity | D24: =('Balance Sheet'!D39+'Balance Sheet'!D46)/'Balance Sheet'!D35 -> 0.032231324 | E24: =('Balance Sheet'!C39+'Balance Sheet'!C46)/'Balance Sheet'!C35 -> 0.047298231 | F24: =(E24-D24)/ABS(D24) -> 0.46746161 | G24: =IF(F24>0,"↑",IF(F24<0,"↓","→")) -> ↑ | H24: Leverage increased, but the debt-to-equity ratio remained at a low level.
B25: Debt Ratio | C25: Total Debt ÷ Total Assets | D25: =('Balance Sheet'!D39+'Balance Sheet'!D46)/'Balance Sheet'!D28 -> 0.028757386 | E25: =('Balance Sheet'!C39+'Balance Sheet'!C46)/'Balance Sheet'!C28 -> 0.041811869 | F25: =(E25-D25)/ABS(D25) -> 0.45395236 | G25: =IF(F25>0,"↑",IF(F25<0,"↓","→")) -> ↑ | H25: Debt as a share of total assets increased, while overall leverage remained relatively low.
B26: Interest Coverage | C26: EBIT ÷ Finance Costs | D26: =('Profit and loss account '!C15+'Cash flow statement '!C8)/'Cash flow statement '!C8 -> 36.617047 | E26: =('Profit and loss account '!B15+'Cash flow statement '!B8)/'Cash flow statement '!B8 -> 39.373675 | F26: =(E26-D26)/ABS(D26) -> 0.075282657 | G26: =IF(F26>0,"↑",IF(F26<0,"↓","→")) -> ↑ | H26: Improved coverage indicates stronger EBIT coverage of finance costs.
H27: (Gross Profit is derived from Revenue less COGS & COGS = Purchase of Stock-in-Trade + Change in Inventories)
A28: 🎯 Key Takeaway | C28: DMart delivered improved profitability and efficiency in FY2022, while liquidity weakened and lease-inclusive leverage increased from a low base. Interest coverage remained strong. | G28: 🤖 AI-Assisted Analysis AI-Enabled Financial Analysis | ChatGPT + Microsoft Copilot
E29: A Project by Ayush Nitin Jagtap | Financial Analysis using AI

Sheet Dashboard 
O1: “Value for Customers. Growth for a Better Tomorrow.”
G2: Financial Analysis Dashboard FY 2021 - FY 2022
B10: Revenue | F10: PBT | J10: PAT | N10: ROCE | R10: Operating Cash Flow
B11: ='Dashboard Data Engine '!E2 -> 30976.27 | F11: ='Dashboard Data Engine '!E4 -> 2064.12 | J11: ='Dashboard Data Engine '!E5 -> 1492.4 | N11: ='Ratio Analysis'!E17/100 -> 0.14857991 | R11: ='Dashboard Data Engine '!E15 -> 1,372.35
B12: ="FY21 ₹"&TEXT('Dashboard Data Engine '!D2,"#,##0.00")&" Cr | "&TEXT('Dashboard Data Engine '!F2,"0.00%") -> FY21 ₹24,143.06 Cr | 28.30% | F12: ="FY21 ₹"&TEXT('Dashboard Data Engine '!D4,"#,##0.00")&" Cr | "&TEXT('Dashboard Data Engine '!F4,"0.00%") -> FY21 ₹1,483.45 Cr | 39.14% | J12: ="FY21 ₹"&TEXT('Dashboard Data Engine '!D5,"#,##0.00")&" Cr | "&TEXT('Dashboard Data Engine '!F5,"0.00%") -> FY21 ₹1,099.43 Cr | 35.74% | N12: ="FY21 "&TEXT('Dashboard Data Engine '!D31,"0.00%")&" | "&TEXT('Dashboard Data Engine '!F31,"0.00%") -> FY21 12.15% | 22.27% | R12: ="FY21 ₹"&TEXT('Dashboard Data Engine '!D15,"#,##0.00")&" Cr | "&TEXT('Dashboard Data Engine '!F15,"0.00%") -> FY21 ₹1,375.14 Cr | -0.20%
B13: DASHBOARD SCOPE | H13: NET WORKING CAPITAL | O13: CHART AREA 1 Revenue / PBT / PAT
B14: Period | D14: FY2021 – FY2022 | H14: ='Dashboard Data Engine '!E22 -> 2224.56
B15: Reporting Basis | D15: Consolidated
B16: Currency | D16: ₹ Crore | H16: ="FY21 ₹"&TEXT('Dashboard Data Engine '!D22,"#,##0.00")&" Cr | "&TEXT('Dashboard Data Engine '!F22,"0.00%") -> FY21 ₹2,955.36 Cr | -24.73%
B17: Source: DMart Annual Report FY2021–22 | H17: Working capital position
B19: CHART AREA 2 Profitability / Margins | H19: CHART AREA 3 Cash Flow / Working Capital
O24: CHART AREA 4 Balance Sheet / Ratios
B31: KEY YEAR-ON-YEAR MOVEMENTS
B32: Financial Metrics | E32: FY 2022 Change (vs. FY 2021)
B33: Revenue Growth | E33: 0.283
B34: PBT Growth | E34: 0.3914
B35: PAT Growth | E35: 0.3574
B36: NWC Change | E36: -0.2473 | O36: PROFITABILITY PBT and PAT grew faster than revenue, with margins improving. LIQUIDITY Current and Quick Ratios declined, indicating a lower short-term liquidity cushion. CASH FLOW Operating cash flow remained broadly stable while investing outflow increased. RETURNS ROCE, ROA and ROE improved year-on-year.
B37: ROCE Improvement | E37: 0.2227
B42: KEY INSIGHTS | O42: FINANCIAL HEALTH SNAPSHOT | R42: AI FEATURE
B43: 1. Revenue & Profit Revenue increased 28.30%, while PBT and PAT grew 39.14% and 35.74%, respectively, indicating stronger profit growth than revenue. 2. Margins PBT margin improved from 6.14% to 6.66%, while PAT margin improved from 4.55% to 4.82%. 3. Liquidity Liquidity weakened, with Current Ratio declining from 3.67× to 2.83× and Quick Ratio from 1.64× to 0.57×. 4. Working Capital Net Working Capital declined 24.73%, while inventory increased 21.99% and trade receivables increased 53.49%. 5. Cash Flow Operating Cash Flow remained broadly stable at ₹1,372.35 Cr, while investing outflow increased to ₹1,289.49 Cr. 6. Returns & Efficiency ROCE improved from 12.15% to 14.86%, while Inventory Turnover and Asset Turnover also increased. | O43: FY2022 Revenue Growth: 28.30% ↑ Profitability: Improved ↑ Liquidity: Weakened ↓ Efficiency: Improved ↑ Leverage: Increased from low base ↗ Cash Flow: Broadly Stable → | S43: AI-ENABLED FINANCIAL ANALYSIS ChatGPT + Microsoft Copilot Used for data cleaning, analysis, insight generation and dashboard structuring.
B50: SOURCE / METHODOLOGY: Based on DMart consolidated financial statements for FY2021–FY2022. Analysis includes financial statement, profitability, liquidity, working capital, cash-flow, efficiency and solvency metrics. Calculations are linked to the underlying analysis sheets for recruiter traceability.
B52: DMART | FINANCIAL ANALYSIS PROJECT | AI-Enabled Financial Analysis | ChatGPT + Microsoft Copilot

Sheet Dashboard Data Engine 
A1: Analysis Area | B1: Metric Category | C1: Metric | D1: FY2021 | E1: FY2022 | F1: Change % | H1: Metric | I1: FY2021 | J1: FY2022
A2: Revenue & Profitability | B2: Growth | C2: Revenue from Operations | D2: ='Revenue & Profitability'!C4 -> 24143.06 | E2: ='Revenue & Profitability'!D4 -> 30976.27 | F2: ='Revenue & Profitability'!E4 -> 0.28302999 | H2: Revenue | I2: =D2 -> 24143.06 | J2: 30976.27
A3: Revenue & Profitability | B3: Growth | C3: Total Income | D3: ='Revenue & Profitability'!C6 -> 24339.27 | E3: ='Revenue & Profitability'!D6 -> 31093.76 | F3: ='Revenue & Profitability'!E6 -> 0.27751407 | H3: PBT | I3: 1483.45 | J3: 2064.12
A4: Revenue & Profitability | B4: Profitability | C4: Profit Before Tax | D4: ='Revenue & Profitability'!H5 -> 1483.45 | E4: ='Revenue & Profitability'!I5 -> 2064.12 | F4: ='Revenue & Profitability'!J5 -> 0.39143213 | H4: PAT | I4: 1099.43 | J4: 1492.4
A5: Revenue & Profitability | B5: Profitability | C5: Profit After Tax | D5: ='Revenue & Profitability'!H6 -> 1099.43 | E5: ='Revenue & Profitability'!I6 -> 1492.4 | F5: ='Revenue & Profitability'!J6 -> 0.35743067
A6: Revenue & Profitability | B6: Profitability | C6: PBT Margin | D6: ='Revenue & Profitability'!H7 -> 0.061444158 | E6: ='Revenue & Profitability'!I7 -> 0.066635525 | F6: ='Revenue & Profitability'!J7 -> 0.084489175 | H6: Metric | I6: FY2021 | J6: FY2022
A7: Revenue & Profitability | B7: Profitability | C7: PAT Margin | D7: ='Revenue & Profitability'!H8 -> 0.045538138 | E7: ='Revenue & Profitability'!I8 -> 0.048178816 | F7: ='Revenue & Profitability'!J8 -> 0.057988263 | H7: Gross Profit Margin | I7: 0.1486 | J7: 0.1478
A8: Balance Sheet | B8: Size | C8: Total Assets | D8: ='Balance Sheet Analysis'!C4 -> 13,655.97 | E8: ='Balance Sheet Analysis'!D4 -> 15,472.64 | F8: ='Balance Sheet Analysis'!E4 -> 0.13303119 | H8: PBT Margin | I8: 0.0614 | J8: 0.0666
A9: Balance Sheet | B9: Size | C9: Total Equity | D9: ='Balance Sheet Analysis'!C5 -> 12,184.11 | E9: ='Balance Sheet Analysis'!D5 -> 13,677.89 | F9: ='Balance Sheet Analysis'!E5 -> 0.12260067 | H9: PAT Margin | I9: 0.0455 | J9: 0.0482
A10: Balance Sheet | B10: Liquidity | C10: Current Assets | D10: ='Balance Sheet Analysis'!C7 -> 4,061.13 | E10: ='Balance Sheet Analysis'!D7 -> 3,442.85 | F10: ='Balance Sheet Analysis'!E7 -> -0.15224334
A11: Balance Sheet | B11: Liquidity | C11: Current Liabilities | D11: ='Balance Sheet Analysis'!C8 -> 1105.77 | E11: ='Balance Sheet Analysis'!D8 -> 1,218.29 | F11: ='Balance Sheet Analysis'!E8 -> 0.10175715 | H11: Metric | I11: FY2021 | J11: FY2022
A12: Balance Sheet | B12: Liquidity | C12: Cash & Cash Equivalents | D12: ='Balance Sheet Analysis'!C9 -> 191.50 | E12: ='Balance Sheet Analysis'!D9 -> 95.12 | F12: ='Balance Sheet Analysis'!E9 -> -0.50328982 | H12: Operating Cash Flow | I12: 1375.14 | J12: 1372.35
A13: Balance Sheet | B13: Working Capital | C13: Inventories | D13: ='Balance Sheet Analysis'!C10 -> 2,248.28 | E13: ='Balance Sheet Analysis'!D10 -> 2,742.66 | F13: ='Balance Sheet Analysis'!E10 -> 0.21989254 | H13: Investing Cash Flow | I13: -1110 | J13: -1289.49
A14: Balance Sheet | B14: Working Capital | C14: Trade Receivables | D14: ='Balance Sheet Analysis'!C11 -> 43.58 | E14: ='Balance Sheet Analysis'!D11 -> 66.89 | F14: ='Balance Sheet Analysis'!E11 -> 0.53487838 | H14: Financing Cash Flow | I14: -179.5 | J14: -179.24
A15: Cash Flow | B15: Cash Flow | C15: Operating Cash Flow | D15: 1375.14 | E15: 1,372.35 | F15: =(E15-D15)/D15 -> -0.0020288843
A16: Cash Flow | B16: Cash Flow | C16: Investing Cash Flow | D16: -1110 | E16: (1,289.49) | F16: -0.1617027 | H16: Metric | I16: FY2021 | J16: FY2022
A17: Cash Flow | B17: Cash Flow | C17: Financing Cash Flow | D17: -179.5 | E17: (179.24) | F17: 0.001448468 | H17: Inventory | I17: 2248.28 | J17: 2742.66
A18: Cash Flow | B18: Cash Flow | C18: Net Cash Movement | D18: 85.64 | E18: (96.38) | F18: -2.1254 | H18: Trade Receivables | I18: 43.58 | J18: 66.89
A19: Working Capital | B19: Working Capital | C19: Inventory | D19: 2248.28 | E19: 2,742.66 | F19: 0.21989254 | H19: Trade Payables | I19: 578.13 | J19: 589.2
A20: Working Capital | B20: Working Capital | C20: Trade Receivables | D20: 43.58 | E20: 66.89 | F20: 0.53487838
A21: Working Capital | B21: Working Capital | C21: Trade Payables | D21: 578.13 | E21: 589.2 | F21: 0.019147943 | H21: Metric | I21: FY2021 | J21: FY2022
A22: Working Capital | B22: Working Capital | C22: Net Working Capital | D22: 2955.36 | E22: 2224.56 | F22: -0.24727952 | H22: Current Ratio | I22: 3.6727 | J22: 2.826
A23: Ratio Analysis | B23: Liquidity | C23: Current Ratio | D23: 3.6727 | E23: 2.826 | F23: -0.2305 | H23: Quick Ratio | I23: 1.6394 | J23: 0.5747
A24: Ratio Analysis | B24: Liquidity | C24: Quick Ratio | D24: 1.6394 | E24: 0.5747 | F24: -0.6494 | H24: Cash Ratio | I24: 0.1732 | J24: 0.0781
A25: Ratio Analysis | B25: Liquidity | C25: Cash Ratio | D25: 0.1732 | E25: 0.0781 | F25: -0.5492
A26: Ratio Analysis | B26: Profitability | C26: Gross Profit Margin | D26: 0.1486 | E26: 0.1478 | F26: -0.0055 | H26: Metric | I26: FY2021 | J26: FY2022
A27: Ratio Analysis | B27: Profitability | C27: PBT Margin | D27: 0.0614 | E27: 0.0666 | F27: 0.0845 | H27: Inventory Turnover | I27: 9.798 | J27: 10.5781
A28: Ratio Analysis | B28: Profitability | C28: PAT Margin | D28: 0.0455 | E28: 0.0482 | F28: 0.058 | H28: Payables Turnover | I28: 41.2336 | J28: 46.074
A29: Ratio Analysis | B29: Profitability | C29: ROA | D29: 0.0805 | E29: 0.0965 | F29: 0.1981 | H29: Asset Turnover | I29: 1.8765 | J29: 2.1269
A30: Ratio Analysis | B30: Profitability | C30: ROE | D30: 0.0902 | E30: 0.1091 | F30: 0.2092
A31: Ratio Analysis | B31: Profitability | C31: ROCE | D31: 0.1215 | E31: 0.1486 | F31: 0.2227 | H31: Metric | I31: FY2021 | J31: FY2022
A32: Ratio Analysis | B32: Efficiency | C32: Inventory Turnover | D32: 9.798 | E32: 10.5781 | F32: 0.0796 | H32: Total Assets | I32: 13655.97 | J32: 15472.64
A33: Ratio Analysis | B33: Efficiency | C33: Receivables Turnover | D33: 764.868 | E33: 560.809 | F33: -0.2668 | H33: Total Equity | I33: 12184.11 | J33: 13677.89
A34: Ratio Analysis | B34: Efficiency | C34: Payables Turnover | D34: 41.2336 | E34: 46.074 | F34: 0.1174
A35: Ratio Analysis | B35: Efficiency | C35: Asset Turnover | D35: 1.8765 | E35: 2.1269 | F35: 0.1334 | H35: Metric | I35: FY2021 | J35: FY2022
A36: Ratio Analysis | B36: Solvency | C36: Debt-to-Equity | D36: 0.0322 | E36: 0.0473 | F36: 0.4675 | H36: ROA | I36: 0.0805 | J36: 0.0965
A37: Ratio Analysis | B37: Solvency | C37: Interest Coverage | D37: 36.617 | E37: 39.374 | F37: 0.0753 | H37: ROE | I37: 0.0902 | J37: 0.1091
H38: ROCE | I38: 0.1215 | J38: 0.1486
